Workbook

Sheet hero
A1: tag | C1: class | D1: tier | E1: slot1Type | F1: slot2Type | G1: slot3Type | H1: slot4Type | I1: slot5Type | J1: slot6Type | K1: slot1Num | L1: slot2Num | M1: slot3Num | N1: slot4Num | O1: slot5Num | P1: slot6Num | Q1: baseHp | R1: baseShield | S1: skillList
A2: militia | B2: 民兵 | C2: fighter | D2: 1 | E2: red | F2: red | G2: red | H2: red | I2: blue | J2: blue | K2: 1 | L2: 1 | M2: 1 | N2: 1 | O2: 1 | P2: 1 | Q2: 5 | R2: 0 | S2: militia_skill1
A3: axeWarrior | B3: 斧战士 | C3: fighter | D3: 2 | E3: red | F3: red | G3: red | H3: red | I3: blue | J3: blue | K3: 2 | L3: 1 | M3: 1 | N3: 1 | O3: 2 | P3: 1 | Q3: 7 | R3: 0 | S3: axeWarrior_skill1
A4: swordsman | B4: 剑士 | C4: fighter | D4: 2 | E4: red | F4: red | G4: red | H4: red | I4: red | J4: blue | K4: 2 | L4: 2 | M4: 1 | N4: 1 | O4: 1 | P4: 1 | Q4: 6 | R4: 0 | S4: swordsman_skill1
A5: greatSwordsman | B5: 大剑士 | C5: fighter | D5: 2 | E5: red | F5: red | G5: red | H5: red | I5: red | J5: blue | K5: 2 | L5: 2 | M5: 1 | N5: 1 | O5: 1 | P5: 1 | Q5: 7 | R5: 0 | S5: greatSwordsman_skill1
A6: fistMaster | B6: 拳师 | C6: fighter | D6: 2 | E6: red | F6: red | G6: red | H6: red | I6: blue | J6: blue | K6: 2 | L6: 2 | M6: 1 | N6: 1 | O6: 1 | P6: 1 | Q6: 5 | R6: 0 | S6: fistMaster_skill1
A7: militiaCaptain | B7: 民兵队长 | C7: fighter | D7: 2 | E7: red | F7: red | G7: red | H7: red | I7: blue | J7: blue | K7: 2 | L7: 2 | M7: 2 | N7: 2 | O7: 2 | P7: 2 | Q7: 7 | R7: 0 | S7: militiaCaptain_skill1
A8: giantAxeKnight | B8: 巨斧骑士 | C8: fighter | D8: 3 | E8: red | F8: red | G8: red | H8: red | I8: blue | J8: green | K8: 4 | L8: 4 | M8: 4 | N8: 1 | O8: 1 | P8: 1 | Q8: 8 | R8: 0 | S8: giantAxeKnight_skill1,giantAxeKnight_skill2
A9: longswordKnight | B9: 长剑骑士 | C9: fighter | D9: 3 | E9: red | F9: red | G9: red | H9: red | I9: blue | J9: blue | K9: 3 | L9: 3 | M9: 3 | N9: 2 | O9: 2 | P9: 2 | Q9: 8 | R9: 0 | S9: longswordKnight_skill1,longswordKnight_skill2
A10: greatswordKnight | B10: 大剑骑士 | C10: fighter | D10: 3 | E10: red | F10: red | G10: red | H10: red | I10: blue | J10: blue | K10: 3 | L10: 3 | M10: 3 | N10: 3 | O10: 1 | P10: 1 | Q10: 9 | R10: 0 | S10: greatswordKnight_skill1,greatswordKnight_skill2
A11: martialArtist | B11: 拳刃骑士 | C11: fighter | D11: 3 | E11: red | F11: red | G11: red | H11: red | I11: red | J11: blue | K11: 3 | L11: 3 | M11: 3 | N11: 2 | O11: 2 | P11: 2 | Q11: 7 | R11: 0 | S11: martialArtist_skill1,martialArtist_skill2
A12: swordKnightOfficer | B12: 剑骑士官 | C12: fighter | D12: 3 | E12: red | F12: red | G12: red | H12: blue | I12: blue | J12: green | K12: 3 | L12: 3 | M12: 3 | N12: 3 | O12: 3 | P12: 3 | Q12: 10 | R12: 0 | S12: swordKnightOfficer_skill1,swordKnightOfficer_skill2
A13: guard | B13: 守卫 | C13: tank | E13: red | F13: red | G13: blue | H13: blue | I13: blue | J13: blue | K13: 1 | L13: 1 | M13: 1 | N13: 1 | O13: 1 | P13: 1 | Q13: 7 | R13: 0 | S13: guard_skill1
A14: shieldBearer | B14: 持盾侍从 | C14: tank | E14: red | F14: red | G14: blue | H14: blue | I14: blue | J14: blue | K14: 2 | L14: 2 | M14: 2 | N14: 2 | O14: 2 | P14: 2 | Q14: 9 | R14: 0 | S14: shieldBearer_skill1,shieldBearer_skill2
A15: shieldFighter | B15: 盾斗士 | C15: tank | E15: red | F15: red | G15: red | H15: blue | I15: blue | J15: blue | K15: 1 | L15: 1 | M15: 1 | N15: 2 | O15: 2 | P15: 1 | Q15: 8 | R15: 0 | S15: shieldFighter_skill1,shieldFighter_skill2
A16: shieldGuard | B16: 盾卫 | C16: tank | E16: red | F16: red | G16: blue | H16: blue | I16: blue | J16: blue | K16: 1 | L16: 1 | M16: 2 | N16: 2 | O16: 1 | P16: 1 | Q16: 8 | R16: 0 | S16: shieldGuard_skill1
A17: apprenticeKnight | B17: 见习骑士 | C17: tank | E17: red | F17: red | G17: blue | H17: blue | I17: blue | J17: blue | K17: 1 | L17: 1 | M17: 2 | N17: 2 | O17: 2 | P17: 1 | Q17: 8 | R17: 0 | S17: apprenticeKnight_skill1,apprenticeKnight_skill2
A18: phalanxSoldier | B18: 方阵士兵 | C18: tank | E18: red | F18: blue | G18: blue | H18: blue | I18: blue | J18: blue | K18: 1 | L18: 2 | M18: 2 | N18: 1 | O18: 1 | P18: 1 | Q18: 9 | R18: 0 | S18: phalanxSoldier_skill1,phalanxSoldier_skill2
A19: shieldOfficer | B19: 盾卫士官 | C19: tank | E19: red | F19: blue | G19: blue | H19: blue | I19: blue | J19: yellow | K19: 3 | L19: 3 | M19: 3 | N19: 3 | O19: 3 | P19: 1 | Q19: 12 | R19: 0 | S19: shieldOfficer_skill1,shieldOfficer_skill2
A20: dualShieldFighter | B20: 双盾斗士 | C20: tank | E20: red | F20: red | G20: red | H20: blue | I20: blue | J20: blue | K20: 3 | L20: 3 | M20: 2 | N20: 2 | O20: 2 | P20: 2 | Q20: 11 | R20: 0 | S20: dualShieldFighter_skill1,dualShieldFighter_skill2
A21: heavyShieldKnight | B21: 重盾骑士 | C21: tank | E21: red | F21: blue | G21: blue | H21: blue | I21: blue | J21: blue | K21: 2 | L21: 3 | M21: 3 | N21: 2 | O21: 2 | P21: 2 | Q21: 10 | R21: 0 | S21: heavyShieldKnight_skill1,heavyShieldKnight_skill2
A22: whiteKnight | B22: 白骑士 | C22: tank | E22: red | F22: blue | G22: blue | H22: blue | I22: blue | J22: green | K22: 1 | L22: 3 | M22: 3 | N22: 2 | O22: 2 | P22: 2 | Q22: 10 | R22: 0 | S22: whiteKnight_skill1,whiteKnight_skill2
A23: bulwarkKnight | B23: 壁垒骑士 | C23: tank | E23: red | F23: blue | G23: blue | H23: blue | I23: blue | J23: green | K23: 1 | L23: 4 | M23: 3 | N23: 3 | O23: 2 | P23: 1 | Q23: 11 | R23: 0 | S23: bulwarkKnight_skill1,bulwarkKnight_skill2
A24: apprentice | B24: 学徒 | C24: mage | E24: red | F24: red | G24: green | H24: green | I24: green | J24: green | K24: 1 | L24: 1 | M24: 1 | N24: 1 | O24: 1 | P24: 1 | Q24: 3 | R24: 0 | S24: apprentice_skill1
... A58: darkPriest | B58: 暗影牧师 | C58: priest | E58: red | F58: red | G58: blue | H58: blue | I58: green | J58: green | K58: 2 | L58: 1 | M58: 2 | N58: 1 | O58: 3 | P58: 3 | Q58: 9 | R58: 0 | S58: darkPriest_skill1,darkPriest_skill2

Sheet monster
A1: tag | C1: class | D1: tier | E1: baseHp | F1: baseShield | G1: skillList
A2: wolf | B2: 狼 | C2: monster | D2: 1 | E2: 4 | F2: 0 | G2: wolf_skill1
A3: blackWolf | B3: 黑狼 | C3: monster | D3: 1 | E3: 5 | F3: 0 | G3: blackWolf_skill1
A4: bandit | B4: 山贼 | C4: monster | D4: 1 | E4: 6 | F4: 0 | G4: bandit_skill1
A5: banditArcher | B5: 山贼弓手 | C5: monster | D5: 1 | E5: 6 | F5: 0 | G5: banditArcher_skill1

Sheet skill
A1: tag | C1: skillName | D1: skillDesc | E1: skillType | F1: skillCost | H1: useType | I1: targetType | J1: hitTarget | K1: dmg | L1: dmgShieldPara | M1: shield | N1: baseBuff | O1: trigger | P1: triggerLimit | Q1: giveBuff | R1: 额外效果（调用子技能） | S1: 伤害目标
A2: militia_skill1 | B2: 民兵 | C2: 劈砍 | D2: 对近战目标造成5点伤害 | E2: skill1 | F2: red,1 | G2: 近战目标 | H2: choose | I2: =VLOOKUP(G2,'$skillTargetType'!$B:$D,2,FALSE) -> melee | J2: =VLOOKUP(G2,'$skillTargetType'!$B:$D,3,FALSE) -> 0,0 | K2: 5 | M2: 0 | S2: enemy
A3: axeWarrior_skill1 | B3: 斧战士 | C3: 巨力纵劈 | D3: 对近战目标及背后相邻单位造成9点伤害 | E3: skill1 | F3: red,2;blue,1 | G3: 近战目标及背后相邻单位 | H3: choose | I3: =VLOOKUP(G3,'$skillTargetType'!$B:$D,2,FALSE) -> melee | J3: =VLOOKUP(G3,'$skillTargetType'!$B:$D,3,FALSE) -> 0,0;0,1 | K3: 9 | M3: 0 | S3: enemy
A4: swordsman_skill1 | B4: 剑士 | C4: 劈砍 | D4: 对近战目标造成12点伤害 | E4: skill1 | F4: red,2 | G4: 近战目标 | H4: choose | I4: =VLOOKUP(G4,'$skillTargetType'!$B:$D,2,FALSE) -> melee | J4: =VLOOKUP(G4,'$skillTargetType'!$B:$D,3,FALSE) -> 0,0 | K4: 12 | M4: 0 | S4: enemy
A5: greatSwordsman_skill1 | B5: 大剑士 | C5: 横扫 | D5: 对近战目标及左右相邻单位造成7点伤害 | E5: skill1 | F5: red,3 | G5: 近战目标及左右相邻单位 | H5: choose | I5: =VLOOKUP(G5,'$skillTargetType'!$B:$D,2,FALSE) -> melee | J5: =VLOOKUP(G5,'$skillTargetType'!$B:$D,3,FALSE) -> 0,0;-1,0;1,0 | K5: 7 | M5: 0 | S5: enemy
A6: fistMaster_skill1 | B6: 拳斗士 | C6: 连打 | D6: 对近战目标造成4点伤害，连击1 | E6: skill1 | F6: red,3 | G6: 近战目标 | H6: choose | I6: =VLOOKUP(G6,'$skillTargetType'!$B:$D,2,FALSE) -> melee | J6: =VLOOKUP(G6,'$skillTargetType'!$B:$D,3,FALSE) -> 0,0 | K6: 4 | M6: 0 | N6: 连击+1 | S6: enemy
A7: militiaCaptain_skill1 | B7: 民兵队长 | C7: 劈砍 | D7: 对近战目标造成8点伤害 | E7: skill1 | F7: red,2 | G7: 近战目标 | H7: choose | I7: =VLOOKUP(G7,'$skillTargetType'!$B:$D,2,FALSE) -> melee | J7: =VLOOKUP(G7,'$skillTargetType'!$B:$D,3,FALSE) -> 0,0 | K7: 8 | M7: 0 | S7: enemy
A8: giantAxeKnight_skill1 | B8: 巨斧骑士 | C8: 巨斧重劈 | D8: 对近战目标及相邻单位造成12点伤害 | E8: skill1 | F8: red,5 | G8: 近战目标及相邻单位 | H8: choose | I8: =VLOOKUP(G8,'$skillTargetType'!$B:$D,2,FALSE) -> melee | J8: =VLOOKUP(G8,'$skillTargetType'!$B:$D,3,FALSE) -> 0,0;0,1;0,-1;-1,0;1,0 | K8: 12 | M8: 0 | S8: enemy
A9: giantAxeKnight_skill2 | B9: 巨斧骑士 | C9: 蓄力 | D9: 自动：自身攻击力+4 | E9: skill2 | F9: red,2;green,2 | G9: 自身 | H9: auto | I9: =VLOOKUP(G9,'$skillTargetType'!$B:$D,2,FALSE) -> self | J9: =VLOOKUP(G9,'$skillTargetType'!$B:$D,3,FALSE) -> 0,0 | K9: 0 | M9: 0 | N9: 攻击力+4
A10: longswordKnight_skill1 | B10: 长剑骑士 | C10: 突击 | D10: 对近战目标造成18点伤害 | E10: skill1 | F10: red,3 | G10: 近战目标 | H10: choose | I10: =VLOOKUP(G10,'$skillTargetType'!$B:$D,2,FALSE) -> melee | J10: =VLOOKUP(G10,'$skillTargetType'!$B:$D,3,FALSE) -> 0,0 | K10: 18 | M10: 0 | S10: enemy
A11: longswordKnight_skill2 | B11: 长剑骑士 | C11: 格挡 | D11: 自动：自身获得6点护甲 | E11: skill2 | F11: blue,2 | G11: 自身 | H11: auto | I11: =VLOOKUP(G11,'$skillTargetType'!$B:$D,2,FALSE) -> self | J11: =VLOOKUP(G11,'$skillTargetType'!$B:$D,3,FALSE) -> 0,0 | K11: 0 | M11: 6
A12: greatswordKnight_skill1 | B12: 大剑骑士 | C12: 横扫 | D12: 对近战目标及左右相邻单位造成11点伤害 | E12: skill1 | F12: red,4 | G12: 近战目标及左右相邻单位 | H12: choose | I12: =VLOOKUP(G12,'$skillTargetType'!$B:$D,2,FALSE) -> melee | J12: =VLOOKUP(G12,'$skillTargetType'!$B:$D,3,FALSE) -> 0,0;-1,0;1,0 | K12: 11 | M12: 0 | S12: enemy
A13: greatswordKnight_skill2 | B13: 大剑骑士 | C13: 连斩 | D13: 自动：为自身的横扫增加连击1 | E13: skill2 | F13: blue,1;green,2 | G13: 自身 | H13: auto | I13: =VLOOKUP(G13,'$skillTargetType'!$B:$D,2,FALSE) -> self | J13: =VLOOKUP(G13,'$skillTargetType'!$B:$D,3,FALSE) -> 0,0 | K13: 0 | M13: 0 | N13: 横扫_连击+1
A14: swordKnightOfficer_skill1 | B14: 剑骑士官 | C14: 率军突击 | D14: 对近战目标造成7点伤害，随后我方前排攻击力+3 | E14: skill1 | F14: red,2;green,2 | G14: 近战目标 | H14: choose | I14: =VLOOKUP(G14,'$skillTargetType'!$B:$D,2,FALSE) -> melee | J14: =VLOOKUP(G14,'$skillTargetType'!$B:$D,3,FALSE) -> 0,0 | K14: 7 | M14: 0 | R14: swordKnightOfficer_skill1_sub | S14: enemy
A15: swordKnightOfficer_skill2 | B15: 剑骑士官 | C15: 坚守战线 | D15: 自动：自身及相邻单位获得3点护甲 | E15: skill2 | F15: blue,4 | G15: 自身及相邻单位 | H15: auto | I15: =VLOOKUP(G15,'$skillTargetType'!$B:$D,2,FALSE) -> self | J15: =VLOOKUP(G15,'$skillTargetType'!$B:$D,3,FALSE) -> 0,0;0,1;0,-1;-1,0;1,0 | K15: 0 | M15: 3
A16: martialArtist_skill1 | B16: 拳刃骑士 | C16: 乱拳连打 | D16: 对近战目标造成4点伤害，连击3 | E16: skill1 | F16: red,4;blue,1 | G16: 近战目标 | H16: choose | I16: =VLOOKUP(G16,'$skillTargetType'!$B:$D,2,FALSE) -> melee | J16: =VLOOKUP(G16,'$skillTargetType'!$B:$D,3,FALSE) -> 0,0 | K16: 4 | M16: 0 | N16: 连击+3 | S16: enemy
A17: martialArtist_skill2 | B17: 拳刃骑士 | C17: 乱拳蓄力 | D17: 自动：为自身的乱拳连打增加连击1 | E17: skill2 | F17: green,3 | G17: 自身 | H17: auto | I17: =VLOOKUP(G17,'$skillTargetType'!$B:$D,2,FALSE) -> self | J17: =VLOOKUP(G17,'$skillTargetType'!$B:$D,3,FALSE) -> 0,0 | K17: 0 | M17: 0 | N17: 乱拳连打_连击+1
A18: guard_skill1 | B18: 守卫 | C18: 持盾攻击 | D18: 对近战目标造成3点伤害，自身获得3点护甲 | E18: skill1 | F18: red,1;blue,1 | G18: 近战目标 | H18: choose | I18: =VLOOKUP(G18,'$skillTargetType'!$B:$D,2,FALSE) -> melee | J18: =VLOOKUP(G18,'$skillTargetType'!$B:$D,3,FALSE) -> 0,0 | K18: 3 | M18: 3 | S18: enemy
A19: shieldBearer_skill1 | B19: 持盾侍从 | C19: 劈砍 | D19: 对近战目标造成7点伤害 | E19: skill1 | F19: red,1 | G19: 近战目标 | H19: choose | I19: =VLOOKUP(G19,'$skillTargetType'!$B:$D,2,FALSE) -> melee | J19: =VLOOKUP(G19,'$skillTargetType'!$B:$D,3,FALSE) -> 0,0 | K19: 7 | M19: 0 | S19: enemy
A20: shieldBearer_skill2 | B20: 持盾侍从 | C20: 保护 | D20: 我方任意单位获得4点护甲 | E20: skill2 | F20: blue,1 | G20: 我方任意单位 | H20: auto | I20: =VLOOKUP(G20,'$skillTargetType'!$B:$D,2,FALSE) -> friendAny | J20: =VLOOKUP(G20,'$skillTargetType'!$B:$D,3,FALSE) -> 0,0 | K20: 0 | M20: 4
A21: shieldFighter_skill1 | B21: 盾斗士 | C21: 持盾突击 | D21: 对近战目标造成3+当前护甲值的伤害 | E21: skill1 | F21: red,2 | G21: 近战目标 | H21: choose | I21: =VLOOKUP(G21,'$skillTargetType'!$B:$D,2,FALSE) -> melee | J21: =VLOOKUP(G21,'$skillTargetType'!$B:$D,3,FALSE) -> 0,0 | K21: 3 | L21: 1 | M21: 0 | S21: enemy
A22: shieldFighter_skill2 | B22: 盾斗士 | C22: 援护 | D22: 自动：我方任意单位和自身获得3点护甲 | E22: skill2 | F22: blue,2 | G22: 我方任意单位和自身 | H22: auto | I22: =VLOOKUP(G22,'$skillTargetType'!$B:$D,2,FALSE) -> friendAnyAndSelf | J22: =VLOOKUP(G22,'$skillTargetType'!$B:$D,3,FALSE) -> 0,0 | K22: 0 | M22: 3
A23: shieldGuard_skill1 | B23: 盾卫 | C23: 持盾攻击 | D23: 对近战目标造成9点伤害，自身获得5点护甲 | E23: skill1 | F23: red,1;blue,2 | G23: 近战目标 | H23: choose | I23: =VLOOKUP(G23,'$skillTargetType'!$B:$D,2,FALSE) -> melee | J23: =VLOOKUP(G23,'$skillTargetType'!$B:$D,3,FALSE) -> 0,0 | K23: 9 | M23: 5 | S23: enemy
A24: apprenticeKnight_skill1 | B24: 见习骑士 | C24: 劈砍 | D24: 对近战目标造成6点伤害 | E24: skill1 | F24: red,1 | G24: 近战目标 | H24: choose | I24: =VLOOKUP(G24,'$skillTargetType'!$B:$D,2,FALSE) -> melee | J24: =VLOOKUP(G24,'$skillTargetType'!$B:$D,3,FALSE) -> 0,0 | K24: 6 | M24: 0 | S24: enemy
A25: apprenticeKnight_skill2 | B25: 见习骑士 | C25: 援护 | D25: 自动：我方任意单位和自身获得3点护甲 | E25: skill2 | F25: blue,2 | G25: 我方任意单位和自身 | H25: auto | I25: =VLOOKUP(G25,'$skillTargetType'!$B:$D,2,FALSE) -> friendAnyAndSelf | J25: =VLOOKUP(G25,'$skillTargetType'!$B:$D,3,FALSE) -> 0,0 | K25: 0 | M25: 3
A26: phalanxSoldier_skill1 | B26: 方阵士兵 | C26: 蓄能冲击 | D26: 对近战目标造成7点伤害，击杀敌人时自身获得3点护甲 | E26: skill1 | F26: red,1;blue,1 | G26: 近战目标 | H26: choose | I26: =VLOOKUP(G26,'$skillTargetType'!$B:$D,2,FALSE) -> melee | J26: =VLOOKUP(G26,'$skillTargetType'!$B:$D,3,FALSE) -> 0,0 | K26: 7 | M26: 0 | O26: kill | P26: 1 | Q26: 击杀敌人时自身护甲+3 | S26: enemy
A27: phalanxSoldier_skill2 | B27: 方阵士兵 | C27: 竖守 | D27: 自动：我方前排获得4点护甲 | E27: skill2 | F27: blue,3 | G27: 我方前排 | H27: auto | I27: =VLOOKUP(G27,'$skillTargetType'!$B:$D,2,FALSE) -> friendMelee | J27: =VLOOKUP(G27,'$skillTargetType'!$B:$D,3,FALSE) -> 0,0 | K27: 0 | M27: 4
A28: shieldOfficer_skill1 | B28: 盾卫士官 | C28: 劈砍 | D28: 对近战目标造成8点伤害 | E28: skill1 | F28: red,3 | G28: 近战目标 | H28: choose | I28: =VLOOKUP(G28,'$skillTargetType'!$B:$D,2,FALSE) -> melee | J28: =VLOOKUP(G28,'$skillTargetType'!$B:$D,3,FALSE) -> 0,0 | K28: 8 | M28: 0 | S28: enemy
A29: shieldOfficer_skill2 | B29: 盾卫士官 | C29: 援护 | D29: 自动：我方任意单位获得5点护甲 | E29: skill2 | F29: blue,1;green,2 | G29: 我方任意单位 | H29: auto | I29: =VLOOKUP(G29,'$skillTargetType'!$B:$D,2,FALSE) -> friendAny | J29: =VLOOKUP(G29,'$skillTargetType'!$B:$D,3,FALSE) -> 0,0 | K29: 0 | M29: 5
A30: dualShieldFighter_skill1 | B30: 双盾斗士 | C30: 二连盾击 | D30: 对近战目标造成4+当前护甲值的伤害，连击1 | E30: skill1 | F30: red,3;blue,2 | G30: 近战目标 | H30: choose | I30: =VLOOKUP(G30,'$skillTargetType'!$B:$D,2,FALSE) -> melee | J30: =VLOOKUP(G30,'$skillTargetType'!$B:$D,3,FALSE) -> 0,0 | K30: 4 | L30: 1 | M30: 0 | N30: 连击+1 | S30: enemy
A31: dualShieldFighter_skill2 | B31: 双盾斗士 | C31: 蓄力 | D31: 自动：自身所在列获得7点护甲，为自身的二连盾击增加连击1 | E31: skill2 | F31: blue,3;green,2 | G31: 自身所在列 | H31: auto | I31: =VLOOKUP(G31,'$skillTargetType'!$B:$D,2,FALSE) -> self | J31: =VLOOKUP(G31,'$skillTargetType'!$B:$D,3,FALSE) -> 0,0;0,1;0,-1;0,2;0,-2;0,3;0,-3;0,4;0,-4 | K31: 0 | M31: 7 | N31: 二连盾击_连击+1
A32: heavyShieldKnight_skill1 | B32: 重盾骑士 | C32: 重盾猛击 | D32: 自身获得6点护甲，之后对近战目标造成等同于自身当前护甲值的伤害 | E32: skill1 | F32: blue,4 | G32: 近战目标 | H32: choose | I32: =VLOOKUP(G32,'$skillTargetType'!$B:$D,2,FALSE) -> melee | J32: =VLOOKUP(G32,'$skillTargetType'!$B:$D,3,FALSE) -> 0,0 | K32: 0 | L32: 1 | M32: 6 | S32: enemy
A33: heavyShieldKnight_skill2 | B33: 重盾骑士 | C33: 阻挡 | D33: 自动：自身所在列获得5点护甲 | E33: skill2 | F33: red,1;blue,2 | G33: 自身所在列 | H33: auto | I33: =VLOOKUP(G33,'$skillTargetType'!$B:$D,2,FALSE) -> self | J33: =VLOOKUP(G33,'$skillTargetType'!$B:$D,3,FALSE) -> 0,0;0,1;0,-1;0,2;0,-2;0,3;0,-3;0,4;0,-4 | K33: 0 | M33: 5
A34: whiteKnight_skill1 | B34: 白骑士 | C34: 二连斩击 | D34: 对近战目标造成6点伤害，连击1 | E34: skill1 | F34: red,2;green,2 | G34: 近战目标 | H34: choose | I34: =VLOOKUP(G34,'$skillTargetType'!$B:$D,2,FALSE) -> melee | J34: =VLOOKUP(G34,'$skillTargetType'!$B:$D,3,FALSE) -> 0,0 | K34: 6 | M34: 0 | N34: 连击+1 | S34: enemy
A35: whiteKnight_skill2 | B35: 白骑士 | C35: 祈福 | D35: 自动：我方任意单位和自身获得4点护甲，且攻击力+2 | E35: skill2 | F35: red,2;blue,2 | G35: 我方任意单位和自身 | H35: auto | I35: =VLOOKUP(G35,'$skillTargetType'!$B:$D,2,FALSE) -> friendAnyAndSelf | J35: =VLOOKUP(G35,'$skillTargetType'!$B:$D,3,FALSE) -> 0,0 | K35: 0 | M35: 4 | N35: 攻击力+2，二连斩击 连击1
A36: bulwarkKnight_skill1 | B36: 壁垒骑士 | C36: 持盾突击 | D36: 对近战目标造成5+当前护甲值的伤害 | E36: skill1 | F36: red,2 | G36: 近战目标 | H36: choose | I36: =VLOOKUP(G36,'$skillTargetType'!$B:$D,2,FALSE) -> melee | J36: =VLOOKUP(G36,'$skillTargetType'!$B:$D,3,FALSE) -> 0,0 | K36: 5 | L36: 1 | M36: 0 | S36: enemy
A37: bulwarkKnight_skill2 | B37: 壁垒骑士 | C37: 壁垒 | D37: 自动：自身所在行获得6点护甲，攻击力+2 | E37: skill2 | F37: blue,4;green,1 | G37: 自身所在行 | H37: auto | I37: =VLOOKUP(G37,'$skillTargetType'!$B:$D,2,FALSE) -> self | J37: =VLOOKUP(G37,'$skillTargetType'!$B:$D,3,FALSE) -> 0,0;-1,0;1,0;-2,0;2,0;-3,0;3,0;-4,0;4,0 | K37: 0 | M37: 6 | N37: 攻击力+2
A38: apprentice_skill1 | B38: 学徒 | C38: 火球 | D38: 对任意目标造成6点伤害 | E38: skill1 | F38: red,1;blue,1 | G38: 任意目标 | H38: choose | I38: =VLOOKUP(G38,'$skillTargetType'!$B:$D,2,FALSE) -> any | J38: =VLOOKUP(G38,'$skillTargetType'!$B:$D,3,FALSE) -> 0,0 | K38: 6 | M38: 0 | S38: enemy
A39: flameApprentice_skill1 | B39: 烈焰学徒 | C39: 大火球 | D39: 对任意目标造成15点伤害 | E39: skill1 | F39: red,1;blue,2 | G39: 任意目标 | H39: choose | I39: =VLOOKUP(G39,'$skillTargetType'!$B:$D,2,FALSE) -> any | J39: =VLOOKUP(G39,'$skillTargetType'!$B:$D,3,FALSE) -> 0,0 | K39: 15 | M39: 0 | S39: enemy
A40: thunderApprentice_skill1 | B40: 雷语学徒 | C40: 雷电术 | D40: 对任意目标造成8点伤害 | E40: skill1 | F40: green,2 | G40: 任意目标 | H40: choose | I40: =VLOOKUP(G40,'$skillTargetType'!$B:$D,2,FALSE) -> any | J40: =VLOOKUP(G40,'$skillTargetType'!$B:$D,3,FALSE) -> 0,0 | K40: 8 | M40: 0 | S40: enemy
...

Sheet skillBuff
B1: targetSkill | C1: buffType | D1: para | H1: 给与buff
A2: =B2&C2&D2 -> combo1 | C2: combo | D2: 1 | H2: 连击+1
A3: =B3&C3&D3 -> addAtk4 | C3: addAtk | D3: 4 | H3: 攻击力+4
A4: =B4&C4&D4 -> skill1combo1 | B4: skill1 | C4: combo | D4: 1 | H4: 横扫_连击+1
A5: =B5&C5&D5 -> addAtk3 | C5: addAtk | D5: 3 | H5: 攻击力+3
A6: =B6&C6&D6 -> combo3 | C6: combo | D6: 3 | H6: 连击+3
A7: =B7&C7&D7 -> skill1combo1 | B7: skill1 | C7: combo | D7: 1 | H7: 乱拳连打_连击+1
A8: =B8&C8&D8 -> addShield3 | C8: addShield | D8: 3 | H8: 击杀敌人时自身护甲+3
A9: =B9&C9&D9 -> skill1combo1 | B9: skill1 | C9: combo | D9: 1 | H9: 二连盾击_连击+1
A10: =B10&C10&D10 -> addAtk2 | C10: addAtk | D10: 2 | H10: 攻击力+2
A11: =B11&C11&D11 -> skill1charge1 | B11: skill1 | C11: charge | D11: 1 | H11: 雷电术_充能+1
A12: =B12&C12&D12 -> skill1addTargetNum1 | B12: skill1 | C12: addTargetNum | D12: 1 | H12: 闪电链_随机目标+1
A13: =B13&C13&D13 -> skill1charge1 | B13: skill1 | C13: charge | D13: 1 | H13: 轰雷术_充能+1
A14: =B14&C14&D14 -> skill1charge1 | B14: skill1 | C14: charge | D14: 1 | H14: 冰枪术_充能+1
A15: =B15&C15&D15 -> addAtk6 | C15: addAtk | D15: 6 | H15: 攻击力+6
A16: =B16&C16&D16 -> addAtk2 | C16: addAtk | D16: 2 | H16: 攻击力+2
A17: =B17&C17&D17 -> skill1addTargetNum2 | B17: skill1 | C17: addTargetNum | D17: 2 | H17: ;大闪电链_随机目标+2
A18: =B18&C18&D18 -> combo2 | C18: combo | D18: 2 | H18: 连击+2
A19: =B19&C19&D19 -> skill1charge1 | B19: skill1 | C19: charge | D19: 1 | H19: 速射_充能+1
A20: =B20&C20&D20 -> skill1charge1 | B20: skill1 | C20: charge | D20: 1 | H20: 刺杀_充能+1
A21: =B21&C21&D21 -> skill1charge1 | B21: skill1 | C21: charge | D21: 1 | H21: 急速散射_充能+1
A22: =B22&C22&D22 -> skill1combo1 | B22: skill1 | C22: combo | D22: 1 | H22: 急速散射_连击+1
A23: =B23&C23&D23 -> skill1combo1 | B23: skill1 | C23: combo | D23: 1 | H23: 贯通连击_连击+1
A24: =B24&C24&D24 -> exposed1 | C24: exposed | D24: 1 | H24: 破碎+1
A25: =B25&C25&D25 -> vulnerable4 | C25: vulnerable | D25: 4 | H25: 重伤+4
A26: =B26&C26&D26 -> addAtk5 | C26: addAtk | D26: 5 | H26: 攻击力+5
A27: =B27&C27&D27 -> skill1charge1 | B27: skill1 | C27: charge | D27: 1 | H27: 灌注_充能+1
A28: =B28&C28&D28 -> skill1charge1 | B28: skill1 | C28: charge | D28: 1 | H28: 闪光术_充能+1

Sheet $skillTargetType
B2: 近战目标 | C2: melee | D2: 0,0
B3: 近战目标及背后相邻单位 | C3: melee | D3: 0,0;0,1
B4: 近战目标及左右相邻单位 | C4: melee | D4: 0,0;-1,0;1,0
B5: 近战目标及相邻单位 | C5: melee | D5: 0,0;0,1;0,-1;-1,0;1,0
B6: 自身 | C6: self | D6: 0,0
B7: 自身及相邻单位 | C7: self | D7: 0,0;0,1;0,-1;-1,0;1,0
B8: 我方前排 | C8: friendMelee | D8: 0,0
B9: 我方任意单位 | C9: friendAny | D9: 0,0
B10: 我方任意单位和自身 | C10: friendAnyAndSelf | D10: 0,0
B11: 自身所在列 | C11: self | D11: 0,0;0,1;0,-1;0,2;0,-2;0,3;0,-3;0,4;0,-4
B12: 自身所在行 | C12: self | D12: 0,0;-1,0;1,0;-2,0;2,0;-3,0;3,0;-4,0;4,0
B13: 任意目标 | C13: any | D13: 0,0
... B15: 近战目标和1个随机目标 | C15: meleeAndRand | D15: 0,0
B16: 相邻单位 | C16: inherit | D16: 0,0;0,1;0,-1;-1,0;1,0 | F16: 目标相邻单位
B17: 任意目标及相邻单位 | C17: any | D17: 0,0;0,1;0,-1;-1,0;1,0
B18: 任意列 | C18: any | D18: 0,0;0,1;0,-1;0,2;0,-2;0,3;0,-3;0,4;0,-4
B19: 近战目标和2个随机目标 | C19: meleeAndRand2 | D19: 0,0
B20: 随机近战目标 | C20: meleeRand
B21: 任意目标及背后相邻单位 | C21: melee | D21: 0,0;0,1
B22: 自身及我方前排 | C22: selfAndfriendMelee | D22: 0,0

Sheet configValue
A1: tag | C1: content
A2: initMapTier | B2: 初始地图tier | C2: 1
A3: initTeamSize | B3: 初始选人上限 | C3: 3
A4: initTeamList | B4: 初始选人列表 | C4: militia,guard,apprentice,hunter,priest
A5: battleMap | C5: {"battle":{1,1;1,2;1,3;1,4;1,5;2,1;2,2;2,3;2,4;2,5;3,2;3,3;3,4},"battleHigh":{1,1;1,2;1,3;1,4;1,5;2,1;2,2;2,3;2,4;2,5;3,1;3,2;3,3;3,4;3,5}}

Sheet map
A1: mapTag | B1: tie
A2: t1_Map1 | B2: 1
B3: 1
B4: 1
A5: t2_Map1 | B5: 2
B6: 2
B7: 2
A8: t3_Map1 | B8: 3
A9: t3_Map2 | B9: 3
A10: t3_Map3 | B10: 3

Sheet mapPoint
A1: tag | B1: mapTag | C1: pointNum | D1: pointType | E1: battleContent | F1: reward1 | G1: reward2 | H1: reward3 | I1: reward4
A2: 1 | B2: t1_Map1 | C2: 1 | D2: battle | E2: battle1,battle2 | F2: exp,9 | G2: coin,10 | H2: coin,10
A3: 2 | B3: t1_Map1 | C3: 2 | D3: battle | E3: battle1,battle2 | F3: exp,9 | G3: coin,10 | H3: coin,10
A4: 3 | B4: t1_Map1 | C4: 3 | D4: start
A5: 4 | B5: t1_Map1 | C5: 4 | D5: battle | E5: battle1,battle2 | F5: exp,9 | G5: coin,10 | H5: coin,10
A6: 5 | B6: t1_Map1 | C6: 5 | D6: battle | E6: battle1,battle2 | F6: exp,9 | G6: coin,10 | H6: coin,10 | L6: t1_Map1
A7: 6 | B7: t1_Map1 | C7: 6 | D7: battle | F7: exp,9 | G7: coin,10 | H7: coin,10 | J7: shop
A8: 7 | B8: t1_Map1 | C8: 7 | D8: battle | E8: battle1,battle2 | F8: exp,9 | G8: coin,10 | H8: coin,10
A9: 8 | B9: t1_Map1 | C9: 8 | D9: battle | E9: battle1,battle2 | F9: exp,9 | G9: coin,10 | H9: coin,10
A10: 9 | B10: t1_Map1 | C10: 9 | D10: rock
A11: 10 | B11: t1_Map1 | C11: 10 | D11: battle | E11: battle1,battle2 | F11: exp,9 | G11: coin,10 | H11: coin,10
A12: 11 | B12: t1_Map1 | C12: 11 | D12: coin | F12: coin,50
A13: 12 | B13: t1_Map1 | C13: 12 | D13: rock
A14: 13 | B14: t1_Map1 | C14: 13 | D14: battle | E14: battle1,battle2 | F14: exp,9 | G14: coin,10 | H14: coin,10
A15: 14 | B15: t1_Map1 | C15: 14 | D15: battle | E15: battle1,battle2 | F15: exp,9 | G15: coin,10 | H15: coin,10
A16: 15 | B16: t1_Map1 | C16: 15 | D16: coin | F16: coin,50
A17: 16 | B17: t1_Map1 | C17: 16 | D17: battle | E17: battle1,battle2 | F17: exp,9 | G17: coin,10 | H17: coin,10
A18: 17 | B18: t1_Map1 | C18: 17 | D18: battleHigh | E18: battle1,battle2 | F18: exp,9 | G18: coin,10 | H18: coin,10
A19: 18 | B19: t1_Map1 | C19: 18 | D19: battle | E19: battle1,battle2 | F19: exp,9 | G19: coin,10 | H19: coin,10
A20: 19 | B20: t1_Map1 | C20: 19 | D20: randWeapon | F20: randWeapon,q3
A21: 20 | B21: t1_Map1 | C21: 20 | D21: battle | E21: battle1,battle2 | F21: exp,9 | G21: coin,10 | H21: coin,10
A22: 21 | B22: t1_Map1 | C22: 21 | D22: randWeapon | F22: randArmor,q2
A23: 22 | B23: t1_Map1 | C23: 22 | D23: rock
A24: 23 | B24: t1_Map1 | C24: 23 | D24: coin | F24: coin,50
A25: 24 | B25: t1_Map1 | C25: 24 | D25: rock
A26: 25 | B26: t1_Map1 | C26: 25 | D26: battle | E26: battle1,battle2 | F26: exp,9 | G26: coin,10 | H26: coin,10
A27: 26 | B27: t1_Map1 | C27: 27 | D27: randWeapon | F27: randWeapon,q3
A28: 27 | B28: t1_Map1 | C28: 28 | D28: battleHigh | E28: battle1,battle2 | F28: exp,9 | G28: coin,10 | H28: coin,10
A29: 28 | B29: t1_Map1 | C29: 29 | D29: battle | F29: exp,9 | G29: coin,10 | H29: coin,10 | J29: shop
A30: 29 | B30: t1_Map1 | C30: 33 | D30: battleBoss | E30: battle1,battle2 | F30: exp,9 | G30: coin,10 | H30: coin,10
A31: 30 | B31: t2_Map1 | C31: 1 | D31: rock
A32: 31 | B32: t2_Map1 | C32: 2 | D32: rock
A33: 32 | B33: t2_Map1 | C33: 3 | D33: start
A34: 33 | B34: t2_Map1 | C34: 4 | D34: rock
A35: 34 | B35: t2_Map1 | C35: 5 | D35: rock
A36: 35 | B36: t2_Map1 | C36: 6 | D36: battle | F36: exp,9 | G36: coin,10 | H36: coin,10
A37: 36 | B37: t2_Map1 | C37: 7 | D37: battle | E37: battle1,battle2 | F37: exp,9 | G37: coin,10 | H37: coin,10
A38: 37 | B38: t2_Map1 | C38: 8 | D38: battle | E38: battle1,battle2 | F38: exp,9 | G38: coin,10 | H38: coin,10
A39: 38 | B39: t2_Map1 | C39: 9 | D39: rock
A40: 39 | B40: t2_Map1 | C40: 10 | D40: battle | E40: battle1,battle2 | F40: exp,9 | G40: coin,10 | H40: coin,10
...

Sheet battleScene
A1: tag | B1: battleScene | C1: munster | D1: x | E1: y
A2: 1 | B2: battle1 | C2: wolf | D2: 2 | E2: 1
A3: 2 | B3: battle1 | C3: bandit | D3: 4 | E3: 1
A4: 3 | B4: battle1 | C4: banditArcher | D4: 1 | E4: 1
A5: 4 | B5: battle2 | C5: wolf | D5: 3 | E5: 2
A6: 5 | B6: battle2 | C6: bandit | D6: 5 | E6: 2
A7: 6 | B7: battle2 | C7: banditArcher | D7: 1 | E7: 2

Sheet $type
A1: tag | C1: 战斗内容
A2: battle | B2: 一场战斗 | C2: 战斗tag数组
A3: battleHigh | B3: 一场随机的精英战斗 | C3: 战斗tag数组
A4: battleBoss | B4: 一场随机的boss战斗 | C4: 战斗tag数组
A5: randWeapon | B5: 随机武器
A6: randArmor | B6: 随机装备
A7: shop | B7: 打开商店
A8: coin | B8: 给钱
A9: rock | B9: 阻挡，不可选择
A10: start | B10: 首次进入这个地图，玩家位置在哪里
A19: 奖励类型 | B19: 说明 | C19: 配置样式 | D19: 解析
A20: exp | B20: 经验 | C20: exp,9 | D20: 9点经验
A21: coin | B21: 金币 | C21: coin,10 | D21: 10个金币
A22: randWeapon | B22: 随机武器 | C22: randWeapon,q3 | D22: 3品质的随机武器
A23: randArmor | B23: 随机防具 | C23: randArmor,q2 | D23: 2品质的随机装备
A25: 特殊奖励规则，如果玩家角色不满6个，最后一份奖励替换为增援
C29: show1 | D29: show2 | E29: show3
B30: 3 | C30: 2 | D30: 8 | E30: 4
B31: 2 | C31: 1 | D31: 7 | E31: X
B32: 7 | C32: 6 | D32: 12 | E32: 13
B33: 6 | C33: 11 | D33: X
B34: 11 | C34: 16 | D34: 17
B35: 17 | C35: X | D35: 22 | E35: 23
B37: here=33 | F37: 切换map到下个tier
B38: MOD(here，5)=3 | C38: here-1 | D38: here+5 | E38: here+1
B39: other | C39: here-1 | D39: here+5 | E39: here+6

Sheet $Sheet1
A1: 给与buff | B1: trigger | C1: targetSkill | D1: buffType | E1: para
A2: 连击+1 | D2: combo | E2: 1 | F2: =C2&D2&E2 -> combo1
A3: 攻击力+4 | D3: addAtk | E3: 4 | F3: =C3&D3&E3 -> addAtk4
A4: 横扫_连击+1 | C4: skill1 | D4: combo | E4: 1 | F4: =C4&D4&E4 -> skill1combo1
A5: 攻击力+3 | D5: addAtk | E5: 3 | F5: =C5&D5&E5 -> addAtk3
A6: 连击+3 | D6: combo | E6: 3 | F6: =C6&D6&E6 -> combo3
A7: 乱拳连打_连击+1 | C7: skill1 | D7: combo | E7: 1 | F7: =C7&D7&E7 -> skill1combo1
A8: 击杀敌人时自身护甲+3 | B8: kill | D8: addShield | E8: 3 | F8: =C8&D8&E8 -> addShield3
A9: 二连盾击_连击+1 | C9: skill1 | D9: combo | E9: 1 | F9: =C9&D9&E9 -> skill1combo1
A10: 攻击力+2 | D10: addAtk | E10: 2 | F10: =C10&D10&E10 -> addAtk2
A11: 雷电术_充能+1 | C11: skill1 | D11: charge | E11: 1 | F11: =C11&D11&E11 -> skill1charge1
A12: 闪电链_随机目标+1 | C12: skill1 | D12: addTargetNum | E12: 1 | F12: =C12&D12&E12 -> skill1addTargetNum1
A13: 轰雷术_充能+1 | C13: skill1 | D13: charge | E13: 1 | F13: =C13&D13&E13 -> skill1charge1
A14: 冰枪术_充能+1 | C14: skill1 | D14: charge | E14: 1 | F14: =C14&D14&E14 -> skill1charge1
A15: 攻击力+6 | D15: addAtk | E15: 6 | F15: =C15&D15&E15 -> addAtk6
A16: 攻击力+2 | D16: addAtk | E16: 2 | F16: =C16&D16&E16 -> addAtk2
A17: ;大闪电链_随机目标+2 | C17: skill1 | D17: addTargetNum | E17: 2 | F17: =C17&D17&E17 -> skill1addTargetNum2
A18: 连击+2 | D18: combo | E18: 2 | F18: =C18&D18&E18 -> combo2
A19: 速射_充能+1 | C19: skill1 | D19: charge | E19: 1 | F19: =C19&D19&E19 -> skill1charge1
A20: 刺杀_充能+1 | C20: skill1 | D20: charge | E20: 1 | F20: =C20&D20&E20 -> skill1charge1
A21: 急速散射_充能+1 | C21: skill1 | D21: charge | E21: 1 | F21: =C21&D21&E21 -> skill1charge1
A22: 急速散射_连击+1 | C22: skill1 | D22: combo | E22: 1 | F22: =C22&D22&E22 -> skill1combo1
A23: 贯通连击_连击+1 | C23: skill1 | D23: combo | E23: 1 | F23: =C23&D23&E23 -> skill1combo1
A24: 破碎+1 | D24: exposed | E24: 1 | F24: =C24&D24&E24 -> exposed1
A25: 重伤+4 | D25: vulnerable | E25: 4 | F25: =C25&D25&E25 -> vulnerable4
A26: 攻击力+5 | D26: addAtk | E26: 5 | F26: =C26&D26&E26 -> addAtk5
A27: 灌注_充能+1 | C27: skill1 | D27: charge | E27: 1 | F27: =C27&D27&E27 -> skill1charge1
A28: 闪光术_充能+1 | C28: skill1 | D28: charge | E28: 1 | F28: =C28&D28&E28 -> skill1charge1
